<?xml version="1.0"?>
<robot xmlns:xacro="http://www.ros.org/wiki/xacro" name="kipp">
    
   <xacro:property name="value" value="value"/>
   
   <link name="base_link">
        <visual>
            <origin xyz="0.0 0.0 0.0" rpy="0.0 0.0 0.0"/>
            <geometry>
                <box size= "0.8 0.5 0.5"/>
            </geometry>
        </visual>
   </link>

   <link name="front_left_steering">
        <visual>
            <origin xyz="0.0 0.0 0.0" rpy="0.0 0.0 0.0"/>
            <geometry>
                <box size="0.1 0.1 0.1"/>
            </geometry>
        </visual>
   </link>

   <link name="front_right_steering">
        <visual>
            <origin xyz="0.0 0.0 0.0" rpy="0.0 0.0 0.0"/>
            <geometry>
                <box size="0.1 0.1 0.1"/>
            </geometry>
        </visual>
   </link>

   <link name="back_left_steering">
        <visual>
            <origin xyz="0.0 0.0 0.0" rpy="0.0 0.0 0.0"/>
            <geometry>
                <box size="0.1 0.1 0.1"/>
            </geometry>
        </visual>
   </link>

   <link name="back_right_steering">
        <visual>
            <origin xyz="0.0 0.0 0.0" rpy="0.0 0.0 0.0"/>
            <geometry>
                <box size="0.1 0.1 0.1"/>
            </geometry>
        </visual>
   </link>

   <joint name="front_left_steering_joint" type="revolute">
    <parent link="base_link"/>
    <child link="front_left_steering"/>
    <axis xyz="0 0 1"/>
    <origin xyz="0.4 0.25 -0.25" rpy="0 0 0"/>
    <limit lower="-1.57" upper="1.57" effort="0.0" velocity="0.0"/>
    
   </joint>

   <joint name="front_right_steering_joint" type="revolute">
    <parent link="base_link"/>
    <child link="front_right_steering"/>
    <axis xyz="0 0 1"/>
    <origin xyz="0.4 -0.25 -0.25" rpy="0 0 0"/>
    <limit lower="-1.57" upper="1.57" effort="0.0" velocity="0.0"/>
    
   </joint>

   <joint name="back_left_steering_joint" type="revolute">
    <parent link="base_link"/>
    <child link="back_left_steering"/>
    <axis xyz="0 0 1"/>
    <origin xyz="-0.4 0.25 -0.25" rpy="0 0 0"/>
    <limit lower="-1.57" upper="1.57" effort="0.0" velocity="0.0"/>
    
   </joint>

   <joint name="back_right_steering_joint" type="revolute">
    <parent link="base_link"/>
    <child link="back_right_steering"/>
    <axis xyz="0 0 1"/>
    <origin xyz="-0.4 -0.25 -0.25" rpy="0 0 0"/>
    <limit lower="-1.57" upper="1.57" effort="0.0" velocity="0.0"/>
    
   </joint>

    <link name="front_left_wheel">
        <visual>
            <origin xyz="0.0 0.0 0.0" rpy="1.57 0.0 0.0"/>
            <geometry>
                <cylinder radius="0.1" length="0.05"/>
            </geometry>
        </visual>
   </link>

       <link name="front_right_wheel">
        <visual>
            <origin xyz="0.0 0.0 0.0" rpy="1.57 0.0 0.0"/>
            <geometry>
                <cylinder radius="0.1" length="0.05"/>
            </geometry>
        </visual>
   </link>

       <link name="middle_left_wheel">
        <visual>
            <origin xyz="0.0 0.0 0.0" rpy="1.57 0.0 0.0"/>
            <geometry>
                <cylinder radius="0.1" length="0.05"/>
            </geometry>
        </visual>
   </link>
       <link name="middle_right_wheel">
        <visual>
            <origin xyz="0.0 0.0 0.0" rpy="1.57 0.0 0.0"/>
            <geometry>
                <cylinder radius="0.1" length="0.05"/>
            </geometry>
        </visual>
   </link>
       <link name="back_left_wheel">
        <visual>
            <origin xyz="0.0 0.0 0.0" rpy="1.57 0.0 0.0"/>
            <geometry>
                <cylinder radius="0.1" length="0.05"/>
            </geometry>
        </visual>
   </link>
       <link name="back_right_wheel">
        <visual>
            <origin xyz="0.0 0.0 0.0" rpy="1.57 0.0 0.0"/>
            <geometry>
                <cylinder radius="0.1" length="0.05"/>
            </geometry>
        </visual>
   </link>

    <joint name="front_left_wheel_joint" type="continuous">
        <parent link="front_left_steering"/>
        <child link="front_left_wheel"/>
        <axis xyz="0 0 0"/>
        <origin xyz="0 0 0" rpy="0 0 0"/>
    </joint>

    <joint name="front_right_wheel_joint" type="continuous">
        <parent link="front_right_steering"/>
        <child link="front_right_wheel"/>
        <axis xyz="0 0 0"/>
        <origin xyz="0 0 0" rpy="0 0 0"/>
    </joint>

    <joint name="middle_left_wheel_joint" type="continuous">
        <parent link="base_link"/>
        <child link="middle_left_wheel"/>
        <axis xyz="0 0 0"/>
        <origin xyz="0 0.25 -0.25" rpy="0 0 0"/>
    </joint>

    <joint name="middle_right_wheel_joint_" type="continuous">
        <parent link="base_link"/>
        <child link="middle_right_wheel"/>
        <axis xyz="0 0 0"/>
        <origin xyz="0 -0.25 -0.25" rpy="0 0 0"/>
    </joint>

    <joint name="back_left_wheel_joint" type="continuous">
        <parent link="back_left_steering"/>
        <child link="back_left_wheel"/>
        <axis xyz="0 0 0"/>
        <origin xyz="0 0 0" rpy="0 0 0"/>
    </joint>

    <joint name="back_right_wheel_joint" type="continuous">
        <parent link="back_right_steering"/>
        <child link="back_right_wheel"/>
        <axis xyz="0 0 0"/>
        <origin xyz="0 0 0" rpy="0 0 0"/>
    </joint>

    
   
</robot>