<robot name="kipps_arm">

    <link name="base_link">
        <visual>
            <origin xyz="0.0 0.0 0.0" rpy="0.0 0.0 0.0"/>
            <geometry>
                <mesh filename="package://description/meshes/base_link.stl"/>
            </geometry>
        </visual>
    </link>

    <link name="base_drum">
        
        <visual>
            <origin xyz="0.0 0.0 0.0" rpy="0.0 0.0 0.0"/>
            <geometry>
                <mesh filename="package://description/meshes/base_drum.stl"/>
            </geometry>
        </visual>
    
    </link>

    <joint name="base_joint" type="revolute">
        <parent link="base_link"/>
        <child link="base_drum"/>
        <axis xyz="0 0 1"/>
        <limit lower="0.00" upper="3.14159" velocity="50.0" effort="1000.0"/>
        <origin xyz="0 0 0.03935" rpy="0 0 0"/>
    </joint>

    <link name="link1">
    <visual>
        <origin xyz="0.0 0.0 0.0" rpy="0.0 0.0 0.0"/>
        <geometry>
            <mesh filename="package://description/meshes/link1.stl"/>
        </geometry>
        
    </visual>
        
    </link>
    
    <joint name="link1_joint" type="revolute">
        <parent link="base_drum"/>
        <child link="link1"/>
        <axis xyz="0 1 0"/>
        <limit lower="-3.14159" upper="3.14159" velocity="50.0" effort="1000.0"/>
        <origin xyz="0 0.0019 0.07018" rpy="0 0 0"/>
    </joint>

    <link name="link2">

    <visual>
        <origin xyz="0.0 0.0 0.0" rpy="0.0 0.0 0.0"/>
        <geometry>
            <mesh filename="package://description/meshes/link2.stl"/>
        </geometry>
    </visual>
        
    </link>
    
    <joint name="link2_joint" type="revolute">
        <parent link="link1"/>
        <child link="link2"/>
        <axis xyz="0 1 0"/>
        <limit lower="-3.14159" upper="3.14159" velocity="50.0" effort="1000.0"/>
        <origin xyz="0.34315 0.01784 0" rpy="0 0 0"/>
    </joint>

    <link name="link3">

    <visual>
        <origin xyz="0.0 0.0 0.0" rpy="0.0 0.0 0.0"/>
        <geometry>
            <mesh filename="package://description/meshes/link3.stl"/>
        </geometry>
    </visual>
        
    </link>
    
    <joint name="link3_joint" type="revolute">
        <parent link="link2"/>
        <child link="link3"/>
        <axis xyz="1 0 0"/>
        <limit lower="-3.14159" upper="3.14159" velocity="50.0" effort="1000.0"/>
        <origin xyz="0.01450 -0.08525 0" rpy="0 0 0"/>
    </joint>

    <link name="link4">

    <visual>
        <origin xyz="0.0 0.0 0.0" rpy="0.0 0.0 0.0"/>
        <geometry>
            <mesh filename="package://description/meshes/link4.stl"/>
        </geometry>
    </visual>
        
    </link>
    
    <joint name="link4_joint" type="revolute">
        <parent link="link3"/>
        <child link="link4"/>
        <axis xyz="0 1 0"/>
        <limit lower="-3.14159" upper="3.14159" velocity="50.0" effort="1000.0"/>
        <origin xyz="0.24068 0.013 0" rpy="0 0 0"/>
    </joint>


        
   <link name="link5">

    <visual>
        <origin xyz="0.0 0.0 0.0" rpy="0.0 0.0 0.0"/>
        <geometry>
            <mesh filename="package://description/meshes/link5.stl"/>
        </geometry>
    </visual>
        
    </link>
    <joint name="eef_joint" type="fixed">
        <parent link="link4"/>
        <child link="link5"/>
        <origin xyz="0.099 0.06567 0.0" rpy="0.0 0.0 0.0"/>
    </joint>
    
</robot>

